Workbook
Name lstBrand: OFFSET('Daily Data'!$T$2,0,0,1+COUNTIF('Daily Data'!$T$3:$T$29,"?*"),1)
Name lstCategory: 'Daily Data'!$Q$2:$Q$4
Name lstDate: OFFSET('Daily Data'!$R$2,0,0,1+COUNT('Daily Data'!$R$3:$R$27),1)
Name lstDay: 'Daily Data'!$S$2:$S$9
Name lstFlavor: 'Daily Data'!$V$2:$V$7
Name lstItem: OFFSET('Daily Data'!$U$2,0,0,1+COUNTIF('Daily Data'!$U$3:$U$29,"?*"),1)
Name lstWeek: 'Daily Data'!$P$2:$P$7

Sheet Dashboard
B1: X Pantry Management - Control Dashboard
B2: ="Stock position as of "&TEXT('Item Purchases'!H1,"dd mmm yyyy")&" | purchase horizon to "&TEXT('Item Purchases'!J1,"dd mmm yyyy")&" | data checks: "&'Accuracy Check'!$B$15&" | forecasts to review: "&(COUNTIF('Accuracy Check'!$S$28:$S$54,"DRIFTING")+COUNTIF('Accuracy Check'!$S$28:$S$54,"POOR")) -> Stock position as of 30 Sep 2026 | purchase horizon to 31 Oct 2026 | data checks: 9 of 9 checks passed | forecasts to review: 14
B3: FILTERS - pick a value in any box below (All = no filter)
B4: WEEK | E4: CATEGORY | H4: FLAVOR PROFILE | K4: DATE | N4: DAY | Q4: BRAND | U4: ITEM
B5: All | E5: All | H5: All | K5: All | N5: All | Q5: All | U5: All
B6: Category / Flavor profile / Brand / Item filter every card and chart. Week / Date / Day also filter the Activity Analysis section (bottom). Set a box back to All to clear it.
B7: PANTRY INSIGHTS - stock in the pantry, what people use and prefer | CV7: STOREHOUSE INSIGHTS - stock held back from the pantry, transfers, spoilage and the stocking decision
B8: ITEMS TRACKED | D8: OUT OF STOCK | F8: CRITICAL | H8: LOW | J8: WATCH | L8: HEALTHY | N8: NO USAGE | P8: ORDER NOW (ITEMS) | R8: CARTONS TO BUY | T8: EST. ORDER COST | V8: COUNT TALLY % | X8: MISMATCHES | CV8: STOREHOUSE STOCK | CY8: STOCK OUT (MTD) | DB8: SPOILED / DAMAGED | DE8: SENT TO PANTRY (NET) | DH8: RECEIVED IN (MTD) | DK8: ITEMS EMPTY | DN8: COVER (DAYS) | DQ8: TRANSFER MISMATCH
B9: =COUNTIFS('Item Purchases'!$W$4:$W$30,1) -> 26 | D9: =COUNTIFS('Item Purchases'!$M$4:$M$30,"OUT OF STOCK",'Item Purchases'!$W$4:$W$30,1) -> 2 | F9: =COUNTIFS('Item Purchases'!$M$4:$M$30,"CRITICAL",'Item Purchases'!$W$4:$W$30,1) -> 4 | H9: =COUNTIFS('Item Purchases'!$M$4:$M$30,"LOW",'Item Purchases'!$W$4:$W$30,1) -> 7 | J9: =COUNTIFS('Item Purchases'!$M$4:$M$30,"WATCH",'Item Purchases'!$W$4:$W$30,1) -> 6 | L9: =COUNTIFS('Item Purchases'!$M$4:$M$30,"HEALTHY",'Item Purchases'!$W$4:$W$30,1) -> 4 | N9: =COUNTIFS('Item Purchases'!$M$4:$M$30,"NO USAGE",'Item Purchases'!$W$4:$W$30,1) -> 3 | P9: =COUNTIFS('Item Purchases'!$O$4:$O$30,">0",'Item Purchases'!$W$4:$W$30,1) -> 22 | R9: =SUMIFS('Item Purchases'!$O$4:$O$30,'Item Purchases'!$W$4:$W$30,1) -> 354 | T9: =SUMIFS('Item Purchases'!$R$4:$R$30,'Item Purchases'!$W$4:$W$30,1) -> 9575.518 | V9: =IF(SUMPRODUCT(ISNUMBER('Storehouse Replenishment Schedu'!$CS$4:$CS$30)*('Item Purchases'!$W$4:$W$30=1))=0,"n/a",SUMPRODUCT(('Storehouse Replenishment Schedu'!$CU$4:$CU$30="TALLY")*('Item Purchases'!$W$4:$W$30=1))/SUMPRODUCT(ISNUMBER('Storehouse Replenishment Schedu'!$CS$4:$CS$30)*('Item Purchases'!$W$4:$W$30=1))) -> 1 | X9: =SUMPRODUCT(('Storehouse Replenishment Schedu'!$CU$4:$CU$30="MISMATCH")*('Item Purchases'!$W$4:$W$30=1)) -> 0 | CV9: =SUMPRODUCT('Storehouse Replenishment Schedu'!$CR$4:$CR$30*('Item Purchases'!$W$4:$W$30=1)) -> 1589 | CY9: =SUMPRODUCT('Storehouse Replenishment Schedu'!$CP$4:$CP$30*('Item Purchases'!$W$4:$W$30=1)) -> 5569 | DB9: =SUMPRODUCT('Storehouse Replenishment Schedu'!$CX$4:$CX$30*('Item Purchases'!$W$4:$W$30=1)) -> 2 | DE9: =CY9-DB9 -> 5567 | DH9: =SUMPRODUCT('Storehouse Replenishment Schedu'!$CQ$4:$CQ$30*('Item Purchases'!$W$4:$W$30=1)) -> 6046 | DK9: =SUMPRODUCT(($BN$17:$BN$43=1)*($BO$17:$BO$43<=0)) -> 10 | DN9: =IF(SUMPRODUCT(($BN$17:$BN$43=1)*$BQ$17:$BQ$43)=0,"n/a",SUMPRODUCT(($BN$17:$BN$43=1)*$BO$17:$BO$43)/SUMPRODUCT(($BN$17:$BN$43=1)*$BQ$17:$BQ$43)) -> 4.9203527 | DQ9: =SUMPRODUCT(ABS($BW$17:$BW$43)*('Item Purchases'!$W$4:$W$30=1)) -> 0
B11: WHAT PEOPLE PREFER - units consumed for the current filters (Flavor profile ignored) (needle = leading type) | R11: STOCK COVER - days left, 10 most urgent items | CV11: STOREHOUSE MOVEMENT AND WHERE THE STOCK SITS (Category / Flavor profile / Brand / Item filters apply)
AB12: FEED FOR GAUGES / CHARTS - formulas, please do not overwrite
AB13: Needle width | AC13: 2 | AD13: (chart units, 200 = full circle)
AH14: FEED FOR ACTIVITY ANALYSIS & ABC - formulas, please do not overwrite
AB15: SNACKS (Sweet vs Savoury) | BM15: FEED FOR STOREHOUSE INSIGHTS - formulas, please do not overwrite | CT15: FEED FOR LOW-PREFERENCE REVIEW - formulas, please do not overwrite
AB16: Type | AC16: Units | AD16: Share % | AE16: Chart label | AF16: Needle | AH16: Date label | AI16: Units | AJ16: Date | AK16: Counted rows | AM16: Day | AN16: Units | AP16: Item | AQ16: Units | AR16: Rank | AT16: Item | AU16: Value | AV16: Rank | AW16: Share | AX16: Cum. share before | AY16: Class | BA16: Rank | BB16: Item (short) | BC16: Value | BD16: Cumulative % | BF16: Class | BG16: Items | BH16: Share of value | BJ16: Class A item | BK16: Value | BM16: Item | BN16: In filter & has usage | BO16: Storehouse stock | BP16: Pantry stock | BQ16: Avg use/day | BR16: Storehouse cover (d) | BS16: Total cover (d) | BT16: Pantry cover (d) | BU16: Stock out MTD | BV16: Pantry received MTD | BW16: Difference | BX16: Action | BY16: Watch rank | BZ16: Gap rank | CA16: Recon flag | CB16: Spoiled / damaged | CC16: Sent to pantry (net) | CD16: Spoilage note | CG16: Date | CH16: Label | CI16: Stock out | CJ16: Received from suppliers | CK16: Pantry received (all items) | CL16: Gap (all items) | CM16: Abs gap | CP16: Flavor profile | CQ16: Storehouse | CR16: Pantry | CT16: Eligible (1/0) | CU16: Preference rank (lowest first)
AB17: Sweet | AC17: =SUMIFS('Daily Data'!$I$2:$I$1000,'Daily Data'!$F$2:$F$1000,$AB17,'Daily Data'!$N$2:$N$1000,1) -> 807 | AD17: =IF($AC$21=0,100/2,AC17/$AC$21*100) -> 47.526502 | AE17: =AB17 -> Sweet | AF17: =$AC$24-$AC$13/2 -> 72.763251 | AH17: =IF(AJ17="","",TEXT(AJ17,"dd mmm")) -> 01 Sep | AI17: =IF(AJ17="","",SUMIFS('Daily Data'!$I$2:$I$1000,'Daily Data'!$A$2:$A$1000,AJ17,'Daily Data'!$M$2:$M$1000,1)) -> 283 | AJ17: ='Daily Data'!$R$3 -> 46266 | AK17: =IF(AJ17="","",COUNTIFS('Daily Data'!$A$2:$A$1000,AJ17,'Daily Data'!$M$2:$M$1000,1,'Daily Data'!$L$2:$L$1000,1)) -> 25 | AM17: Tue | AN17: =SUMIFS('Daily Data'!$I$2:$I$1000,'Daily Data'!$B$2:$B$1000,AM17,'Daily Data'!$M$2:$M$1000,1) -> 1180 | AP17: =IF('Item Purchases'!$B$4="","",'Item Purchases'!$B$4) -> Julie's Peanut Butter Sandwich 360g (12pkts x 30g) | AQ17: =IF(AP17="","",SUMIFS('Daily Data'!$I$2:$I$1000,'Daily Data'!$E$2:$E$1000,AP17,'Daily Data'!$M$2:$M$1000,1)) -> 197 | AR17: =IF(AP17="","",SUMPRODUCT(ISNUMBER($AQ$17:$AQ$43)*($AQ$17:$AQ$43>AQ17))+SUMPRODUCT(ISNUMBER($AQ$17:AQ17)*($AQ$17:AQ17=AQ17))) -> 13 | AT17: =AP17 -> Julie's Peanut Butter Sandwich 360g (12pkts x 30g) | AU17: =IF(AT17="","",SUMIFS('Daily Data'!$K$2:$K$1000,'Daily Data'!$E$2:$E$1000,AT17,'Daily Data'!$M$2:$M$1000,1)) -> 213.351 | AV17: =IF(OR(AT17="",N(AU17)<=0),"",SUMPRODUCT(ISNUMBER($AU$17:$AU$43)*($AU$17:$AU$43>AU17))+SUMPRODUCT(ISNUMBER($AU$17:AU17)*($AU$17:AU17=AU17))) -> 14 | AW17: =IF(AV17="","",AU17/$AU$45) -> 0.020733446 | AX17: =IF(AV17="","",SUMIFS($AU$17:$AU$43,$AV$17:$AV$43,"<"&AV17)/$AU$45) -> 0.86752357 | AY17: =IF(AT17="","",IF(AV17="","-",IF(AX17<'Item Purchases'!$E$49,"A",IF(AX17<'Item Purchases'!$E$50,"B","C")))) -> B | BA17: 1 | BB17: =IFERROR(LEFT(INDEX($AT$17:$AT$43,MATCH(1,$AV$17:$AV$43,0)),20),"") -> Lays Double Crunch - | BC17: =IFERROR(INDEX($AU$17:$AU$43,MATCH(1,$AV$17:$AV$43,0)),0) -> 1260 | BD17: =IF($AU$45=0,0,IFERROR(INDEX($AX$17:$AX$43,MATCH(1,$AV$17:$AV$43,0))+INDEX($AW$17:$AW$43,MATCH(1,$AV$17:$AV$43,0)),1)) -> 0.12244678 | BF17: A | BG17: =COUNTIF($AY$17:$AY$43,BF17) -> 11 | BH17: =IF($AU$45=0,0,SUMIFS($AU$17:$AU$43,$AY$17:$AY$43,BF17)/$AU$45) -> 0.80748286 | BJ17: =IF(1>$BG$17,"",INDEX($AT$17:$AT$43,MATCH(1,$AV$17:$AV$43,0))) -> Lays Double Crunch - Seaweed Flav (50g) | BK17: =IF(1>$BG$17,"",INDEX($AU$17:$AU$43,MATCH(1,$AV$17:$AV$43,0))) -> 1260 | BM17: =IF('Item Purchases'!$B4="","",'Item Purchases'!$B4) -> Julie's Peanut Butter Sandwich 360g (12pkts x 30g) | BN17: =IF(AND(BM17<>"",'Item Purchases'!$W4=1,'Item Purchases'!$AN4<>"Discontinued",N('Item Purchases'!$C4)>0),1,0) -> 1 | BO17: =N('Storehouse Replenishment Schedu'!$CR4) -> 48 | BP17: =N('Item Purchases'!$E4) -> 36 | BQ17: =N('Item Purchases'!$C4) -> 8.9545455 | BR17: =IF(BN17=1,BO17/BQ17,"") -> 5.3604061 | BS17: =IF(BN17=1,(BO17+BP17)/BQ17,"") -> 9.3807107 | BT17: =IF(BN17=1,BP17/BQ17,"") -> 4.0203046 | BU17: =N('Storehouse Replenishment Schedu'!$CP4) -> 192 | BV17: =IF(BM17="",0,SUMIFS('Daily Data'!$G$2:$G$1000,'Daily Data'!$E$2:$E$1000,BM17)) -> 192 | BW17: =CC17-BV17 -> 0 | BX17: =IF(BN17<>1,"",IF(BO17<=0,IF(BT17<='Item Purchases'!$E$38,"EMPTY - ORDER NOW","EMPTY - PLAN ORDER"),IF(BR17<='Item Purchases'!$E$51,"ORDER NOW",IF(BT17<='Item Purchases'!$E$38,"TRANSFER TO PANTRY",IF(BR17<='Item Purchases'!$E$39,"WATCH","OK"))))) -> TRANSFER TO PANTRY | BY17: =IF(BN17=1,SUMPRODUCT(($BN$17:$BN$43=1)*(($BR$17:$BR$43<BR17)+($BR$17:$BR$43=BR17)*($BT$17:$BT$43<BT17)))+SUMPRODUCT(($BN$17:$BN17=1)*($BR$17:$BR17=BR17)*($BT$17:$BT17=BT17)),"") -> 15 | BZ17: =IF(CA17>0,COUNTIF($CA$17:$CA$43,">"&CA17)+COUNTIF($CA$17:CA17,CA17),"") | CA17: =IF(AND(BM17<>"",'Item Purchases'!$W4=1),ABS(BW17)*1000+CB17,0) -> 0 | CB17: =N('Storehouse Replenishment Schedu'!$CX4) -> 0 | CC17: =BU17-CB17 -> 192 | CD17: =IF('Storehouse Replenishment Schedu'!$CY4="","",'Storehouse Replenishment Schedu'!$CY4) | CG17: =INDEX('Storehouse Replenishment Schedu'!$D$2:$CO$2,1,1) -> 46266 | CH17: =IF(CG17="","",TEXT(CG17,"dd mmm")) -> 01 Sep | CI17: =SUMPRODUCT(INDEX('Storehouse Replenishment Schedu'!$D$4:$CO$30,0,1)*('Item Purchases'!$W$4:$W$30=1)) -> 267 | CJ17: =SUMPRODUCT(INDEX('Storehouse Replenishment Schedu'!$D$4:$CO$30,0,2)*('Item Purchases'!$W$4:$W$30=1)) -> 89 | CK17: =IF(CG17="",0,SUMIFS('Daily Data'!$G$2:$G$1000,'Daily Data'!$A$2:$A$1000,CG17)) -> 267 | CL17: =SUMPRODUCT(INDEX('Storehouse Replenishment Schedu'!$D$4:$CO$30,0,1))-CK17 -> 0 | CM17: =ABS(CL17) -> 0 | CP17: Sweet | CQ17: =SUMPRODUCT(('Item Purchases'!$S$4:$S$30=CP17)*('Item Purchases'!$W$4:$W$30=1)*'Storehouse Replenishment Schedu'!$CR$4:$CR$30) -> 88 | CR17: =SUMPRODUCT(('Item Purchases'!$S$4:$S$30=CP17)*('Item Purchases'!$W$4:$W$30=1)*'Item Purchases'!$E$4:$E$30) -> 138 | CT17: =IF(AND(BM17<>"",'Item Purchases'!$W4=1,ISNUMBER('Item Purchases'!$AQ4),'Item Purchases'!$AS4<>"DISCONTINUED",'Item Purchases'!$AS4<>"NEED MORE DATA"),1,0) -> 1 | CU17: =IF(CT17=1,SUMPRODUCT(($CT$17:$CT$43=1)*('Item Purchases'!$AQ$4:$AQ$30<'Item Purchases'!$AQ4))+SUMPRODUCT(($CT$17:$CT17=1)*('Item Purchases'!$AQ$4:$AQ4='Item Purchases'!$AQ4)),"") -> 13
AB18: Savoury | AC18: =SUMIFS('Daily Data'!$I$2:$I$1000,'Daily Data'!$F$2:$F$1000,$AB18,'Daily Data'!$N$2:$N$1000,1) -> 891 | AD18: =IF($AC$21=0,100/2,AC18/$AC$21*100) -> 52.473498 | AE18: =AB18 -> Savoury | AF18: =$AC$13 -> 2 | AH18: =IF(AJ18="","",TEXT(AJ18,"dd mmm")) -> 02 Sep | AI18: =IF(AJ18="","",SUMIFS('Daily Data'!$I$2:$I$1000,'Daily Data'!$A$2:$A$1000,AJ18,'Daily Data'!$M$2:$M$1000,1)) -> 273 | AJ18: ='Daily Data'!$R$4 -> 46267 | AK18: =IF(AJ18="","",COUNTIFS('Daily Data'!$A$2:$A$1000,AJ18,'Daily Data'!$M$2:$M$1000,1,'Daily Data'!$L$2:$L$1000,1)) -> 25 | AM18: Wed | AN18: =SUMIFS('Daily Data'!$I$2:$I$1000,'Daily Data'!$B$2:$B$1000,AM18,'Daily Data'!$M$2:$M$1000,1) -> 1146 | AP18: =IF('Item Purchases'!$B$5="","",'Item Purchases'!$B$5) -> Julies Butter Waffles | AQ18: =IF(AP18="","",SUMIFS('Daily Data'!$I$2:$I$1000,'Daily Data'!$E$2:$E$1000,AP18,'Daily Data'!$M$2:$M$1000,1)) -> 32 | AR18: =IF(AP18="","",SUMPRODUCT(ISNUMBER($AQ$17:$AQ$43)*($AQ$17:$AQ$43>AQ18))+SUMPRODUCT(ISNUMBER($AQ$17:AQ18)*($AQ$17:AQ18=AQ18))) -> 22 | AT18: =AP18 -> Julies Butter Waffles | AU18: =IF(AT18="","",SUMIFS('Daily Data'!$K$2:$K$1000,'Daily Data'!$E$2:$E$1000,AT18,'Daily Data'!$M$2:$M$1000,1)) -> 164.8 | AV18: =IF(OR(AT18="",N(AU18)<=0),"",SUMPRODUCT(ISNUMBER($AU$17:$AU$43)*($AU$17:$AU$43>AU18))+SUMPRODUCT(ISNUMBER($AU$17:AU18)*($AU$17:AU18=AU18))) -> 16 | AW18: =IF(AV18="","",AU18/$AU$45) -> 0.016015261 | AX18: =IF(AV18="","",SUMIFS($AU$17:$AU$43,$AV$17:$AV$43,"<"&AV18)/$AU$45) -> 0.90847531 | AY18: =IF(AT18="","",IF(AV18="","-",IF(AX18<'Item Purchases'!$E$49,"A",IF(AX18<'Item Purchases'!$E$50,"B","C")))) -> B | BA18: 2 | BB18: =IFERROR(LEFT(INDEX($AT$17:$AT$43,MATCH(2,$AV$17:$AV$43,0)),20),"") -> COWA Coconut Water 3 | BC18: =IFERROR(INDEX($AU$17:$AU$43,MATCH(2,$AV$17:$AV$43,0)),0) -> 1248 | BD18: =IF($AU$45=0,0,IFERROR(INDEX($AX$17:$AX$43,MATCH(2,$AV$17:$AV$43,0))+INDEX($AW$17:$AW$43,MATCH(2,$AV$17:$AV$43,0)),1)) -> 0.2437274 | BF18: B | BG18: =COUNTIF($AY$17:$AY$43,BF18) -> 7 | BH18: =IF($AU$45=0,0,SUMIFS($AU$17:$AU$43,$AY$17:$AY$43,BF18)/$AU$45) -> 0.14419017 | BJ18: =IF(2>$BG$17,"",INDEX($AT$17:$AT$43,MATCH(2,$AV$17:$AV$43,0))) -> COWA Coconut Water 330 ml | BK18: =IF(2>$BG$17,"",INDEX($AU$17:$AU$43,MATCH(2,$AV$17:$AV$43,0))) -> 1248 | BM18: =IF('Item Purchases'!$B5="","",'Item Purchases'!$B5) -> Julies Butter Waffles | BN18: =IF(AND(BM18<>"",'Item Purchases'!$W5=1,'Item Purchases'!$AN5<>"Discontinued",N('Item Purchases'!$C5)>0),1,0) -> 1 | BO18: =N('Storehouse Replenishment Schedu'!$CR5) -> 0 | BP18: =N('Item Purchases'!$E5) -> 0 | BQ18: =N('Item Purchases'!$C5) -> 1.6842105 | BR18: =IF(BN18=1,BO18/BQ18,"") -> 0 | BS18: =IF(BN18=1,(BO18+BP18)/BQ18,"") -> 0 | BT18: =IF(BN18=1,BP18/BQ18,"") -> 0 | BU18: =N('Storehouse Replenishment Schedu'!$CP5) -> 20 | BV18: =IF(BM18="",0,SUMIFS('Daily Data'!$G$2:$G$1000,'Daily Data'!$E$2:$E$1000,BM18)) -> 20 | BW18: =CC18-BV18 -> 0 | BX18: =IF(BN18<>1,"",IF(BO18<=0,IF(BT18<='Item Purchases'!$E$38,"EMPTY - ORDER NOW","EMPTY - PLAN ORDER"),IF(BR18<='Item Purchases'!$E$51,"ORDER NOW",IF(BT18<='Item Purchases'!$E$38,"TRANSFER TO PANTRY",IF(BR18<='Item Purchases'!$E$39,"WATCH","OK"))))) -> EMPTY - ORDER NOW | BY18: =IF(BN18=1,SUMPRODUCT(($BN$17:$BN$43=1)*(($BR$17:$BR$43<BR18)+($BR$17:$BR$43=BR18)*($BT$17:$BT$43<BT18)))+SUMPRODUCT(($BN$17:$BN18=1)*($BR$17:$BR18=BR18)*($BT$17:$BT18=BT18)),"") -> 1 | BZ18: =IF(CA18>0,COUNTIF($CA$17:$CA$43,">"&CA18)+COUNTIF($CA$17:CA18,CA18),"") | CA18: =IF(AND(BM18<>"",'Item Purchases'!$W5=1),ABS(BW18)*1000+CB18,0) -> 0 | CB18: =N('Storehouse Replenishment Schedu'!$CX5) -> 0 | CC18: =BU18-CB18 -> 20 | CD18: =IF('Storehouse Replenishment Schedu'!$CY5="","",'Storehouse Replenishment Schedu'!$CY5) | CG18: =INDEX('Storehouse Replenishment Schedu'!$D$2:$CO$2,1,4) -> 46267 | CH18: =IF(CG18="","",TEXT(CG18,"dd mmm")) -> 02 Sep | CI18: =SUMPRODUCT(INDEX('Storehouse Replenishment Schedu'!$D$4:$CO$30,0,4)*('Item Purchases'!$W$4:$W$30=1)) -> 120 | CJ18: =SUMPRODUCT(INDEX('Storehouse Replenishment Schedu'!$D$4:$CO$30,0,5)*('Item Purchases'!$W$4:$W$30=1)) -> 0 | CK18: =IF(CG18="",0,SUMIFS('Daily Data'!$G$2:$G$1000,'Daily Data'!$A$2:$A$1000,CG18)) -> 120 | CL18: =SUMPRODUCT(INDEX('Storehouse Replenishment Schedu'!$D$4:$CO$30,0,4))-CK18 -> 0 | CM18: =ABS(CL18) -> 0 | CP18: Savoury | CQ18: =SUMPRODUCT(('Item Purchases'!$S$4:$S$30=CP18)*('Item Purchases'!$W$4:$W$30=1)*'Storehouse Replenishment Schedu'!$CR$4:$CR$30) -> 601 | CR18: =SUMPRODUCT(('Item Purchases'!$S$4:$S$30=CP18)*('Item Purchases'!$W$4:$W$30=1)*'Item Purchases'!$E$4:$E$30) -> 171 | CT18: =IF(AND(BM18<>"",'Item Purchases'!$W5=1,ISNUMBER('Item Purchases'!$AQ5),'Item Purchases'!$AS5<>"DISCONTINUED",'Item Purchases'!$AS5<>"NEED MORE DATA"),1,0) -> 1 | CU18: =IF(CT18=1,SUMPRODUCT(($CT$17:$CT$43=1)*('Item Purchases'!$AQ$4:$AQ$30<'Item Purchases'!$AQ5))+SUMPRODUCT(($CT$17:$CT18=1)*('Item Purchases'!$AQ$4:$AQ5='Item Purchases'!$AQ5)),"") -> 5
AB19: (hidden half) | AD19: 100 | AE19: =IF($AC$21=0,"No consumption data yet",UPPER($AC$22)&" leads · "&TEXT(MAX($AD$17:$AD$18)/100,"0%")&" of "&TEXT($AC$21,"#,##0")&" units") -> SAVOURY leads · 52% of 1,698 units | AF19: =100-$AC$24-$AC$13/2 -> 25.236749 | AH19: =IF(AJ19="","",TEXT(AJ19,"dd mmm")) -> 03 Sep | AI19: =IF(AJ19="","",SUMIFS('Daily Data'!$I$2:$I$1000,'Daily Data'!$A$2:$A$1000,AJ19,'Daily Data'!$M$2:$M$1000,1)) -> 196 | AJ19: ='Daily Data'!$R$5 -> 46268 | AK19: =IF(AJ19="","",COUNTIFS('Daily Data'!$A$2:$A$1000,AJ19,'Daily Data'!$M$2:$M$1000,1,'Daily Data'!$L$2:$L$1000,1)) -> 25 | AM19: Thu | AN19: =SUMIFS('Daily Data'!$I$2:$I$1000,'Daily Data'!$B$2:$B$1000,AM19,'Daily Data'!$M$2:$M$1000,1) -> 1083 | AP19: =IF('Item Purchases'!$B$6="","",'Item Purchases'!$B$6) -> Julies Choco More Sandwich (44G) | AQ19: =IF(AP19="","",SUMIFS('Daily Data'!$I$2:$I$1000,'Daily Data'!$E$2:$E$1000,AP19,'Daily Data'!$M$2:$M$1000,1)) -> 100 | AR19: =IF(AP19="","",SUMPRODUCT(ISNUMBER($AQ$17:$AQ$43)*($AQ$17:$AQ$43>AQ19))+SUMPRODUCT(ISNUMBER($AQ$17:AQ19)*($AQ$17:AQ19=AQ19))) -> 18 | AT19: =AP19 -> Julies Choco More Sandwich (44G) | AU19: =IF(AT19="","",SUMIFS('Daily Data'!$K$2:$K$1000,'Daily Data'!$E$2:$E$1000,AT19,'Daily Data'!$M$2:$M$1000,1)) -> 120 | AV19: =IF(OR(AT19="",N(AU19)<=0),"",SUMPRODUCT(ISNUMBER($AU$17:$AU$43)*($AU$17:$AU$43>AU19))+SUMPRODUCT(ISNUMBER($AU$17:AU19)*($AU$17:AU19=AU19))) -> 21 | AW19: =IF(AV19="","",AU19/$AU$45) -> 0.011661598 | AX19: =IF(AV19="","",SUMIFS($AU$17:$AU$43,$AV$17:$AV$43,"<"&AV19)/$AU$45) -> 0.97665081 | AY19: =IF(AT19="","",IF(AV19="","-",IF(AX19<'Item Purchases'!$E$49,"A",IF(AX19<'Item Purchases'!$E$50,"B","C")))) -> C | BA19: 3 | BB19: =IFERROR(LEFT(INDEX($AT$17:$AT$43,MATCH(3,$AV$17:$AV$43,0)),20),"") -> Oat Side Chocolate 2 | BC19: =IFERROR(INDEX($AU$17:$AU$43,MATCH(3,$AV$17:$AV$43,0)),0) -> 1149 | BD19: =IF($AU$45=0,0,IFERROR(INDEX($AX$17:$AX$43,MATCH(3,$AV$17:$AV$43,0))+INDEX($AW$17:$AW$43,MATCH(3,$AV$17:$AV$43,0)),1)) -> 0.3553872 | BF19: C | BG19: =COUNTIF($AY$17:$AY$43,BF19) -> 5 | BH19: =IF($AU$45=0,0,SUMIFS($AU$17:$AU$43,$AY$17:$AY$43,BF19)/$AU$45) -> 0.048326974 | BJ19: =IF(3>$BG$17,"",INDEX($AT$17:$AT$43,MATCH(3,$AV$17:$AV$43,0))) -> Oat Side Chocolate 200ml | BK19: =IF(3>$BG$17,"",INDEX($AU$17:$AU$43,MATCH(3,$AV$17:$AV$43,0))) -> 1149 | BM19: =IF('Item Purchases'!$B6="","",'Item Purchases'!$B6) -> Julies Choco More Sandwich (44G) | BN19: =IF(AND(BM19<>"",'Item Purchases'!$W6=1,'Item Purchases'!$AN6<>"Discontinued",N('Item Purchases'!$C6)>0),1,0) -> 1 | BO19: =N('Storehouse Replenishment Schedu'!$CR6) -> 40 | BP19: =N('Item Purchases'!$E6) -> 20 | BQ19: =N('Item Purchases'!$C6) -> 10 | BR19: =IF(BN19=1,BO19/BQ19,"") -> 4 | BS19: =IF(BN19=1,(BO19+BP19)/BQ19,"") -> 6 | BT19: =IF(BN19=1,BP19/BQ19,"") -> 2 | BU19: =N('Storehouse Replenishment Schedu'!$CP6) -> 120 | BV19: =IF(BM19="",0,SUMIFS('Daily Data'!$G$2:$G$1000,'Daily Data'!$E$2:$E$1000,BM19)) -> 120 | BW19: =CC19-BV19 -> 0 | BX19: =IF(BN19<>1,"",IF(BO19<=0,IF(BT19<='Item Purchases'!$E$38,"EMPTY - ORDER NOW","EMPTY - PLAN ORDER"),IF(BR19<='Item Purchases'!$E$51,"ORDER NOW",IF(BT19<='Item Purchases'!$E$38,"TRANSFER TO PANTRY",IF(BR19<='Item Purchases'!$E$39,"WATCH","OK"))))) -> ORDER NOW | BY19: =IF(BN19=1,SUMPRODUCT(($BN$17:$BN$43=1)*(($BR$17:$BR$43<BR19)+($BR$17:$BR$43=BR19)*($BT$17:$BT$43<BT19)))+SUMPRODUCT(($BN$17:$BN19=1)*($BR$17:$BR19=BR19)*($BT$17:$BT19=BT19)),"") -> 14 | BZ19: =IF(CA19>0,COUNTIF($CA$17:$CA$43,">"&CA19)+COUNTIF($CA$17:CA19,CA19),"") | CA19: =IF(AND(BM19<>"",'Item Purchases'!$W6=1),ABS(BW19)*1000+CB19,0) -> 0 | CB19: =N('Storehouse Replenishment Schedu'!$CX6) -> 0 | CC19: =BU19-CB19 -> 120 | CD19: =IF('Storehouse Replenishment Schedu'!$CY6="","",'Storehouse Replenishment Schedu'!$CY6) | CG19: =INDEX('Storehouse Replenishment Schedu'!$D$2:$CO$2,1,7) -> 46268 | CH19: =IF(CG19="","",TEXT(CG19,"dd mmm")) -> 03 Sep | CI19: =SUMPRODUCT(INDEX('Storehouse Replenishment Schedu'!$D$4:$CO$30,0,7)*('Item Purchases'!$W$4:$W$30=1)) -> 261 | CJ19: =SUMPRODUCT(INDEX('Storehouse Replenishment Schedu'!$D$4:$CO$30,0,8)*('Item Purchases'!$W$4:$W$30=1)) -> 0 | CK19: =IF(CG19="",0,SUMIFS('Daily Data'!$G$2:$G$1000,'Daily Data'!$A$2:$A$1000,CG19)) -> 261 | CL19: =SUMPRODUCT(INDEX('Storehouse Replenishment Schedu'!$D$4:$CO$30,0,7))-CK19 -> 0 | CM19: =ABS(CL19) -> 0 | CP19: Coffee | CQ19: =SUMPRODUCT(('Item Purchases'!$S$4:$S$30=CP19)*('Item Purchases'!$W$4:$W$30=1)*'Storehouse Replenishment Schedu'!$CR$4:$CR$30) -> 48 | CR19: =SUMPRODUCT(('Item Purchases'!$S$4:$S$30=CP19)*('Item Purchases'!$W$4:$W$30=1)*'Item Purchases'!$E$4:$E$30) -> 77 | CT19: =IF(AND(BM19<>"",'Item Purchases'!$W6=1,ISNUMBER('Item Purchases'!$AQ6),'Item Purchases'!$AS6<>"DISCONTINUED",'Item Purchases'!$AS6<>"NEED MORE DATA"),1,0) -> 1 | CU19: =IF(CT19=1,SUMPRODUCT(($CT$17:$CT$43=1)*('Item Purchases'!$AQ$4:$AQ$30<'Item Purchases'!$AQ6))+SUMPRODUCT(($CT$17:$CT19=1)*('Item Purchases'!$AQ$4:$AQ6='Item Purchases'!$AQ6)),"") -> 14
AF20: 100 | AH20: =IF(AJ20="","",TEXT(AJ20,"dd mmm")) -> 04 Sep | AI20: =IF(AJ20="","",SUMIFS('Daily Data'!$I$2:$I$1000,'Daily Data'!$A$2:$A$1000,AJ20,'Daily Data'!$M$2:$M$1000,1)) -> 206 | AJ20: ='Daily Data'!$R$6 -> 46269 | AK20: =IF(AJ20="","",COUNTIFS('Daily Data'!$A$2:$A$1000,AJ20,'Daily Data'!$M$2:$M$1000,1,'Daily Data'!$L$2:$L$1000,1)) -> 25 | AM20: Fri | AN20: =SUMIFS('Daily Data'!$I$2:$I$1000,'Daily Data'!$B$2:$B$1000,AM20,'Daily Data'!$M$2:$M$1000,1) -> 960 | AP20: =IF('Item Purchases'!$B$7="","",'Item Purchases'!$B$7) -> Julies Cheese Sandwich (28G) | AQ20: =IF(AP20="","",SUMIFS('Daily Data'!$I$2:$I$1000,'Daily Data'!$E$2:$E$1000,AP20,'Daily Data'!$M$2:$M$1000,1)) -> 129 | AR20: =IF(AP20="","",SUMPRODUCT(ISNUMBER($AQ$17:$AQ$43)*($AQ$17:$AQ$43>AQ20))+SUMPRODUCT(ISNUMBER($AQ$17:AQ20)*($AQ$17:AQ20=AQ20))) -> 16 | AT20: =AP20 -> Julies Cheese Sandwich (28G) | AU20: =IF(AT20="","",SUMIFS('Daily Data'!$K$2:$K$1000,'Daily Data'!$E$2:$E$1000,AT20,'Daily Data'!$M$2:$M$1000,1)) -> 141.9 | AV20: =IF(OR(AT20="",N(AU20)<=0),"",SUMPRODUCT(ISNUMBER($AU$17:$AU$43)*($AU$17:$AU$43>AU20))+SUMPRODUCT(ISNUMBER($AU$17:AU20)*($AU$17:AU20=AU20))) -> 17 | AW20: =IF(AV20="","",AU20/$AU$45) -> 0.01378984 | AX20: =IF(AV20="","",SUMIFS($AU$17:$AU$43,$AV$17:$AV$43,"<"&AV20)/$AU$45) -> 0.92449057 | AY20: =IF(AT20="","",IF(AV20="","-",IF(AX20<'Item Purchases'!$E$49,"A",IF(AX20<'Item Purchases'!$E$50,"B","C")))) -> B | BA20: 4 | BB20: =IFERROR(LEFT(INDEX($AT$17:$AT$43,MATCH(4,$AV$17:$AV$43,0)),20),"") -> Oat Side Original 20 | BC20: =IFERROR(INDEX($AU$17:$AU$43,MATCH(4,$AV$17:$AV$43,0)),0) -> 891 | BD20: =IF($AU$45=0,0,IFERROR(INDEX($AX$17:$AX$43,MATCH(4,$AV$17:$AV$43,0))+INDEX($AW$17:$AW$43,MATCH(4,$AV$17:$AV$43,0)),1)) -> 0.44197456 | BJ20: =IF(4>$BG$17,"",INDEX($AT$17:$AT$43,MATCH(4,$AV$17:$AV$43,0))) -> Oat Side Original 200ml | BK20: =IF(4>$BG$17,"",INDEX($AU$17:$AU$43,MATCH(4,$AV$17:$AV$43,0))) -> 891 | BM20: =IF('Item Purchases'!$B7="","",'Item Purchases'!$B7) -> Julies Cheese Sandwich (28G) | BN20: =IF(AND(BM20<>"",'Item Purchases'!$W7=1,'Item Purchases'!$AN7<>"Discontinued",N('Item Purchases'!$C7)>0),1,0) -> 1 | BO20: =N('Storehouse Replenishment Schedu'!$CR7) -> 36 | BP20: =N('Item Purchases'!$E7) -> 18 | BQ20: =N('Item Purchases'!$C7) -> 6.45 | BR20: =IF(BN20=1,BO20/BQ20,"") -> 5.5813953 | BS20: =IF(BN20=1,(BO20+BP20)/BQ20,"") -> 8.372093 | BT20: =IF(BN20=1,BP20/BQ20,"") -> 2.7906977 | BU20: =N('Storehouse Replenishment Schedu'!$CP7) -> 96 | BV20: =IF(BM20="",0,SUMIFS('Daily Data'!$G$2:$G$1000,'Daily Data'!$E$2:$E$1000,BM20)) -> 96 | BW20: =CC20-BV20 -> 0 | BX20: =IF(BN20<>1,"",IF(BO20<=0,IF(BT20<='Item Purchases'!$E$38,"EMPTY - ORDER NOW","EMPTY - PLAN ORDER"),IF(BR20<='Item Purchases'!$E$51,"ORDER NOW",IF(BT20<='Item Purchases'!$E$38,"TRANSFER TO PANTRY",IF(BR20<='Item Purchases'!$E$39,"WATCH","OK"))))) -> TRANSFER TO PANTRY | BY20: =IF(BN20=1,SUMPRODUCT(($BN$17:$BN$43=1)*(($BR$17:$BR$43<BR20)+($BR$17:$BR$43=BR20)*($BT$17:$BT$43<BT20)))+SUMPRODUCT(($BN$17:$BN20=1)*($BR$17:$BR20=BR20)*($BT$17:$BT20=BT20)),"") -> 16 | BZ20: =IF(CA20>0,COUNTIF($CA$17:$CA$43,">"&CA20)+COUNTIF($CA$17:CA20,CA20),"") | CA20: =IF(AND(BM20<>"",'Item Purchases'!$W7=1),ABS(BW20)*1000+CB20,0) -> 0 | CB20: =N('Storehouse Replenishment Schedu'!$CX7) -> 0 | CC20: =BU20-CB20 -> 96 | CD20: =IF('Storehouse Replenishment Schedu'!$CY7="","",'Storehouse Replenishment Schedu'!$CY7) | CG20: =INDEX('Storehouse Replenishment Schedu'!$D$2:$CO$2,1,10) -> 46269 | CH20: =IF(CG20="","",TEXT(CG20,"dd mmm")) -> 04 Sep | CI20: =SUMPRODUCT(INDEX('Storehouse Replenishment Schedu'!$D$4:$CO$30,0,10)*('Item Purchases'!$W$4:$W$30=1)) -> 0 | CJ20: =SUMPRODUCT(INDEX('Storehouse Replenishment Schedu'!$D$4:$CO$30,0,11)*('Item Purchases'!$W$4:$W$30=1)) -> 540 | CK20: =IF(CG20="",0,SUMIFS('Daily Data'!$G$2:$G$1000,'Daily Data'!$A$2:$A$1000,CG20)) -> 0 | CL20: =SUMPRODUCT(INDEX('Storehouse Replenishment Schedu'!$D$4:$CO$30,0,10))-CK20 -> 0 | CM20: =ABS(CL20) -> 0 | CP20: Tea | CQ20: =SUMPRODUCT(('Item Purchases'!$S$4:$S$30=CP20)*('Item Purchases'!$W$4:$W$30=1)*'Storehouse Replenishment Schedu'!$CR$4:$CR$30) -> 132 | CR20: =SUMPRODUCT(('Item Purchases'!$S$4:$S$30=CP20)*('Item Purchases'!$W$4:$W$30=1)*'Item Purchases'!$E$4:$E$30) -> 90 | CT20: =IF(AND(BM20<>"",'Item Purchases'!$W7=1,ISNUMBER('Item Purchases'!$AQ7),'Item Purchases'!$AS7<>"DISCONTINUED",'Item Purchases'!$AS7<>"NEED MORE DATA"),1,0) -> 1 | CU20: =IF(CT20=1,SUMPRODUCT(($CT$17:$CT$43=1)*('Item Purchases'!$AQ$4:$AQ$30<'Item Purchases'!$AQ7))+SUMPRODUCT(($CT$17:$CT20=1)*('Item Purchases'!$AQ$4:$AQ7='Item Purchases'!$AQ7)),"") -> 9
AB21: Total units | AC21: =SUM($AC$17:$AC$18) -> 1698 | AH21: =IF(AJ21="","",TEXT(AJ21,"dd mmm")) -> 07 Sep | AI21: =IF(AJ21="","",SUMIFS('Daily Data'!$I$2:$I$1000,'Daily Data'!$A$2:$A$1000,AJ21,'Daily Data'!$M$2:$M$1000,1)) -> 183 | AJ21: ='Daily Data'!$R$7 -> 46272 | AK21: =IF(AJ21="","",COUNTIFS('Daily Data'!$A$2:$A$1000,AJ21,'Daily Data'!$M$2:$M$1000,1,'Daily Data'!$L$2:$L$1000,1)) -> 25 | AM21: Sat | AN21: =SUMIFS('Daily Data'!$I$2:$I$1000,'Daily Data'!$B$2:$B$1000,AM21,'Daily Data'!$M$2:$M$1000,1) -> 0 | AP21: =IF('Item Purchases'!$B$8="","",'Item Purchases'!$B$8) -> NV OATS & DARK CHOC 42GX5 | AQ21: =IF(AP21="","",SUMIFS('Daily Data'!$I$2:$I$1000,'Daily Data'!$E$2:$E$1000,AP21,'Daily Data'!$M$2:$M$1000,1)) -> 11 | AR21: =IF(AP21="","",SUMPRODUCT(ISNUMBER($AQ$17:$AQ$43)*($AQ$17:$AQ$43>AQ21))+SUMPRODUCT(ISNUMBER($AQ$17:AQ21)*($AQ$17:AQ21=AQ21))) -> 23 | AT21: =AP21 -> NV OATS & DARK CHOC 42GX5 | AU21: =IF(AT21="","",SUMIFS('Daily Data'!$K$2:$K$1000,'Daily Data'!$E$2:$E$1000,AT21,'Daily Data'!$M$2:$M$1000,1)) -> 30.58 | AV21: =IF(OR(AT21="",N(AU21)<=0),"",SUMPRODUCT(ISNUMBER($AU$17:$AU$43)*($AU$17:$AU$43>AU21))+SUMPRODUCT(ISNUMBER($AU$17:AU21)*($AU$17:AU21=AU21))) -> 23 | AW21: =IF(AV21="","",AU21/$AU$45) -> 0.0029717639 | AX21: =IF(AV21="","",SUMIFS($AU$17:$AU$43,$AV$17:$AV$43,"<"&AV21)/$AU$45) -> 0.99702824 | AY21: =IF(AT21="","",IF(AV21="","-",IF(AX21<'Item Purchases'!$E$49,"A",IF(AX21<'Item Purchases'!$E$50,"B","C")))) -> C | BA21: 5 | BB21: =IFERROR(LEFT(INDEX($AT$17:$AT$43,MATCH(5,$AV$17:$AV$43,0)),20),"") -> Spritzer sparkling w | BC21: =IFERROR(INDEX($AU$17:$AU$43,MATCH(5,$AV$17:$AV$43,0)),0) -> 853.6 | BD21: =IF($AU$45=0,0,IFERROR(INDEX($AX$17:$AX$43,MATCH(5,$AV$17:$AV$43,0))+INDEX($AW$17:$AW$43,MATCH(5,$AV$17:$AV$43,0)),1)) -> 0.52492739 | BJ21: =IF(5>$BG$17,"",INDEX($AT$17:$AT$43,MATCH(5,$AV$17:$AV$43,0))) -> Spritzer sparkling water (original) 400ml | BK21: =IF(5>$BG$17,"",INDEX($AU$17:$AU$43,MATCH(5,$AV$17:$AV$43,0))) -> 853.6 | BM21: =IF('Item Purchases'!$B8="","",'Item Purchases'!$B8) -> NV OATS & DARK CHOC 42GX5 | BN21: =IF(AND(BM21<>"",'Item Purchases'!$W8=1,'Item Purchases'!$AN8<>"Discontinued",N('Item Purchases'!$C8)>0),1,0) -> 1 | BO21: =N('Storehouse Replenishment Schedu'!$CR8) -> 0 | BP21: =N('Item Purchases'!$E8) -> 0 | BQ21: =N('Item Purchases'!$C8) -> 5.5 | BR21: =IF(BN21=1,BO21/BQ21,"") -> 0 | BS21: =IF(BN21=1,(BO21+BP21)/BQ21,"") -> 0 | BT21: =IF(BN21=1,BP21/BQ21,"") -> 0 | BU21: =N('Storehouse Replenishment Schedu'!$CP8) -> 0 | BV21: =IF(BM21="",0,SUMIFS('Daily Data'!$G$2:$G$1000,'Daily Data'!$E$2:$E$1000,BM21)) -> 0 | BW21: =CC21-BV21 -> 0 | BX21: =IF(BN21<>1,"",IF(BO21<=0,IF(BT21<='Item Purchases'!$E$38,"EMPTY - ORDER NOW","EMPTY - PLAN ORDER"),IF(BR21<='Item Purchases'!$E$51,"ORDER NOW",IF(BT21<='Item Purchases'!$E$38,"TRANSFER TO PANTRY",IF(BR21<='Item Purchases'!$E$39,"WATCH","OK"))))) -> EMPTY - ORDER NOW | BY21: =IF(BN21=1,SUMPRODUCT(($BN$17:$BN$43=1)*(($BR$17:$BR$43<BR21)+($BR$17:$BR$43=BR21)*($BT$17:$BT$43<BT21)))+SUMPRODUCT(($BN$17:$BN21=1)*($BR$17:$BR21=BR21)*($BT$17:$BT21=BT21)),"") -> 2 | BZ21: =IF(CA21>0,COUNTIF($CA$17:$CA$43,">"&CA21)+COUNTIF($CA$17:CA21,CA21),"") | CA21: =IF(AND(BM21<>"",'Item Purchases'!$W8=1),ABS(BW21)*1000+CB21,0) -> 0 | CB21: =N('Storehouse Replenishment Schedu'!$CX8) -> 0 | CC21: =BU21-CB21 -> 0 | CD21: =IF('Storehouse Replenishment Schedu'!$CY8="","",'Storehouse Replenishment Schedu'!$CY8) | CG21: =INDEX('Storehouse Replenishment Schedu'!$D$2:$CO$2,1,13) -> 46270 | CH21: =IF(CG21="","",TEXT(CG21,"dd mmm")) -> 05 Sep | CI21: =SUMPRODUCT(INDEX('Storehouse Replenishment Schedu'!$D$4:$CO$30,0,13)*('Item Purchases'!$W$4:$W$30=1)) -> 0 | CJ21: =SUMPRODUCT(INDEX('Storehouse Replenishment Schedu'!$D$4:$CO$30,0,14)*('Item Purchases'!$W$4:$W$30=1)) -> 0 | CK21: =IF(CG21="",0,SUMIFS('Daily Data'!$G$2:$G$1000,'Daily Data'!$A$2:$A$1000,CG21)) -> 0 | CL21: =SUMPRODUCT(INDEX('Storehouse Replenishment Schedu'!$D$4:$CO$30,0,13))-CK21 -> 0 | CM21: =ABS(CL21) -> 0 | CP21: Other | CQ21: =SUMPRODUCT(('Item Purchases'!$S$4:$S$30=CP21)*('Item Purchases'!$W$4:$W$30=1)*'Storehouse Replenishment Schedu'!$CR$4:$CR$30) -> 720 | CR21: =SUMPRODUCT(('Item Purchases'!$S$4:$S$30=CP21)*('Item Purchases'!$W$4:$W$30=1)*'Item Purchases'!$E$4:$E$30) -> 542 | CT21: =IF(AND(BM21<>"",'Item Purchases'!$W8=1,ISNUMBER('Item Purchases'!$AQ8),'Item Purchases'!$AS8<>"DISCONTINUED",'Item Purchases'!$AS8<>"NEED MORE DATA"),1,0) -> 0 | CU21: =IF(CT21=1,SUMPRODUCT(($CT$17:$CT$43=1)*('Item Purchases'!$AQ$4:$AQ$30<'Item Purchases'!$AQ8))+SUMPRODUCT(($CT$17:$CT21=1)*('Item Purchases'!$AQ$4:$AQ8='Item Purchases'!$AQ8)),"")
AB22: Leading type | AC22: =INDEX($AB$17:$AB$18,$AC$23) -> Savoury | AH22: =IF(AJ22="","",TEXT(AJ22,"dd mmm")) -> 08 Sep | AI22: =IF(AJ22="","",SUMIFS('Daily Data'!$I$2:$I$1000,'Daily Data'!$A$2:$A$1000,AJ22,'Daily Data'!$M$2:$M$1000,1)) -> 143 | AJ22: ='Daily Data'!$R$8 -> 46273 | AK22: =IF(AJ22="","",COUNTIFS('Daily Data'!$A$2:$A$1000,AJ22,'Daily Data'!$M$2:$M$1000,1,'Daily Data'!$L$2:$L$1000,1)) -> 25 | AM22: Sun | AN22: =SUMIFS('Daily Data'!$I$2:$I$1000,'Daily Data'!$B$2:$B$1000,AM22,'Daily Data'!$M$2:$M$1000,1) -> 0 | AP22: =IF('Item Purchases'!$B$9="","",'Item Purchases'!$B$9) -> NV PROTEIN - SALTED CARAMEL 40G | AQ22: =IF(AP22="","",SUMIFS('Daily Data'!$I$2:$I$1000,'Daily Data'!$E$2:$E$1000,AP22,'Daily Data'!$M$2:$M$1000,1)) -> 0 | AR22: =IF(AP22="","",SUMPRODUCT(ISNUMBER($AQ$17:$AQ$43)*($AQ$17:$AQ$43>AQ22))+SUMPRODUCT(ISNUMBER($AQ$17:AQ22)*($AQ$17:AQ22=AQ22))) -> 24 | AT22: =AP22 -> NV PROTEIN - SALTED CARAMEL 40G | AU22: =IF(AT22="","",SUMIFS('Daily Data'!$K$2:$K$1000,'Daily Data'!$E$2:$E$1000,AT22,'Daily Data'!$M$2:$M$1000,1)) -> 0 | AV22: =IF(OR(AT22="",N(AU22)<=0),"",SUMPRODUCT(ISNUMBER($AU$17:$AU$43)*($AU$17:$AU$43>AU22))+SUMPRODUCT(ISNUMBER($AU$17:AU22)*($AU$17:AU22=AU22))) | AW22: =IF(AV22="","",AU22/$AU$45) | AX22: =IF(AV22="","",SUMIFS($AU$17:$AU$43,$AV$17:$AV$43,"<"&AV22)/$AU$45) | AY22: =IF(AT22="","",IF(AV22="","-",IF(AX22<'Item Purchases'!$E$49,"A",IF(AX22<'Item Purchases'!$E$50,"B","C")))) -> - | BA22: 6 | BB22: =IFERROR(LEFT(INDEX($AT$17:$AT$43,MATCH(6,$AV$17:$AV$43,0)),20),"") -> Ayataka Tea 300ml | BC22: =IFERROR(INDEX($AU$17:$AU$43,MATCH(6,$AV$17:$AV$43,0)),0) -> 712.25 | BD22: =IF($AU$45=0,0,IFERROR(INDEX($AX$17:$AX$43,MATCH(6,$AV$17:$AV$43,0))+INDEX($AW$17:$AW$43,MATCH(6,$AV$17:$AV$43,0)),1)) -> 0.59414384 | BJ22: =IF(6>$BG$17,"",INDEX($AT$17:$AT$43,MATCH(6,$AV$17:$AV$43,0))) -> Ayataka Tea 300ml | BK22: =IF(6>$BG$17,"",INDEX($AU$17:$AU$43,MATCH(6,$AV$17:$AV$43,0))) -> 712.25 | BM22: =IF('Item Purchases'!$B9="","",'Item Purchases'!$B9) -> NV PROTEIN - SALTED CARAMEL 40G | BN22: =IF(AND(BM22<>"",'Item Purchases'!$W9=1,'Item Purchases'!$AN9<>"Discontinued",N('Item Purchases'!$C9)>0),1,0) -> 0 | BO22: =N('Storehouse Replenishment Schedu'!$CR9) -> 0 | BP22: =N('Item Purchases'!$E9) -> 0 | BQ22: =N('Item Purchases'!$C9) -> 0 | BR22: =IF(BN22=1,BO22/BQ22,"") | BS22: =IF(BN22=1,(BO22+BP22)/BQ22,"") | BT22: =IF(BN22=1,BP22/BQ22,"") | BU22: =N('Storehouse Replenishment Schedu'!$CP9) -> 0 | BV22: =IF(BM22="",0,SUMIFS('Daily Data'!$G$2:$G$1000,'Daily Data'!$E$2:$E$1000,BM22)) -> 0 | BW22: =CC22-BV22 -> 0 | BX22: =IF(BN22<>1,"",IF(BO22<=0,IF(BT22<='Item Purchases'!$E$38,"EMPTY - ORDER NOW","EMPTY - PLAN ORDER"),IF(BR22<='Item Purchases'!$E$51,"ORDER NOW",IF(BT22<='Item Purchases'!$E$38,"TRANSFER TO PANTRY",IF(BR22<='Item Purchases'!$E$39,"WATCH","OK"))))) | BY22: =IF(BN22=1,SUMPRODUCT(($BN$17:$BN$43=1)*(($BR$17:$BR$43<BR22)+($BR$17:$BR$43=BR22)*($BT$17:$BT$43<BT22)))+SUMPRODUCT(($BN$17:$BN22=1)*($BR$17:$BR22=BR22)*($BT$17:$BT22=BT22)),"") | BZ22: =IF(CA22>0,COUNTIF($CA$17:$CA$43,">"&CA22)+COUNTIF($CA$17:CA22,CA22),"") | CA22: =IF(AND(BM22<>"",'Item Purchases'!$W9=1),ABS(BW22)*1000+CB22,0) -> 0 | CB22: =N('Storehouse Replenishment Schedu'!$CX9) -> 0 | CC22: =BU22-CB22 -> 0 | CD22: =IF('Storehouse Replenishment Schedu'!$CY9="","",'Storehouse Replenishment Schedu'!$CY9) | CG22: =INDEX('Storehouse Replenishment Schedu'!$D$2:$CO$2,1,16) -> 46271 | CH22: =IF(CG22="","",TEXT(CG22,"dd mmm")) -> 06 Sep | CI22: =SUMPRODUCT(INDEX('Storehouse Replenishment Schedu'!$D$4:$CO$30,0,16)*('Item Purchases'!$W$4:$W$30=1)) -> 0 | CJ22: =SUMPRODUCT(INDEX('Storehouse Replenishment Schedu'!$D$4:$CO$30,0,17)*('Item Purchases'!$W$4:$W$30=1)) -> 124 | CK22: =IF(CG22="",0,SUMIFS('Daily Data'!$G$2:$G$1000,'Daily Data'!$A$2:$A$1000,CG22)) -> 0 | CL22: =SUMPRODUCT(INDEX('Storehouse Replenishment Schedu'!$D$4:$CO$30,0,16))-CK22 -> 0 | CM22: =ABS(CL22) -> 0 | CT22: =IF(AND(BM22<>"",'Item Purchases'!$W9=1,ISNUMBER('Item Purchases'!$AQ9),'Item Purchases'!$AS9<>"DISCONTINUED",'Item Purchases'!$AS9<>"NEED MORE DATA"),1,0) -> 1 | CU22: =IF(CT22=1,SUMPRODUCT(($CT$17:$CT$43=1)*('Item Purchases'!$AQ$4:$AQ$30<'Item Purchases'!$AQ9))+SUMPRODUCT(($CT$17:$CT22=1)*('Item Purchases'!$AQ$4:$AQ9='Item Purchases'!$AQ9)),"") -> 1
AB23: Leader position | AC23: =MATCH(MAX($AD$17:$AD$18),$AD$17:$AD$18,0) -> 2 | AH23: =IF(AJ23="","",TEXT(AJ23,"dd mmm")) -> 09 Sep | AI23: =IF(AJ23="","",SUMIFS('Daily Data'!$I$2:$I$1000,'Daily Data'!$A$2:$A$1000,AJ23,'Daily Data'!$M$2:$M$1000,1)) -> 327 | AJ23: ='Daily Data'!$R$9 -> 46274 | AK23: =IF(AJ23="","",COUNTIFS('Daily Data'!$A$2:$A$1000,AJ23,'Daily Data'!$M$2:$M$1000,1,'Daily Data'!$L$2:$L$1000,1)) -> 25 | AM23: Mon | AN23: =SUMIFS('Daily Data'!$I$2:$I$1000,'Daily Data'!$B$2:$B$1000,AM23,'Daily Data'!$M$2:$M$1000,1) -> 803 | AP23: =IF('Item Purchases'!$B$10="","",'Item Purchases'!$B$10) -> BBMG 90G | AQ23: =IF(AP23="","",SUMIFS('Daily Data'!$I$2:$I$1000,'Daily Data'!$E$2:$E$1000,AP23,'Daily Data'!$M$2:$M$1000,1)) -> 362 | AR23: =IF(AP23="","",SUMPRODUCT(ISNUMBER($AQ$17:$AQ$43)*($AQ$17:$AQ$43>AQ23))+SUMPRODUCT(ISNUMBER($AQ$17:AQ23)*($AQ$17:AQ23=AQ23))) -> 5 | AT23: =AP23 -> BBMG 90G | AU23: =IF(AT23="","",SUMIFS('Daily Data'!$K$2:$K$1000,'Daily Data'!$E$2:$E$1000,AT23,'Daily Data'!$M$2:$M$1000,1)) -> 124.166 | AV23: =IF(OR(AT23="",N(AU23)<=0),"",SUMPRODUCT(ISNUMBER($AU$17:$AU$43)*($AU$17:$AU$43>AU23))+SUMPRODUCT(ISNUMBER($AU$17:AU23)*($AU$17:AU23=AU23))) -> 20 | AW23: =IF(AV23="","",AU23/$AU$45) -> 0.01206645 | AX23: =IF(AV23="","",SUMIFS($AU$17:$AU$43,$AV$17:$AV$43,"<"&AV23)/$AU$45) -> 0.96458436 | AY23: =IF(AT23="","",IF(AV23="","-",IF(AX23<'Item Purchases'!$E$49,"A",IF(AX23<'Item Purchases'!$E$50,"B","C")))) -> C | BA23: 7 | BB23: =IFERROR(LEFT(INDEX($AT$17:$AT$43,MATCH(7,$AV$17:$AV$43,0)),20),"") -> Oolong Tea 300ml | BC23: =IFERROR(INDEX($AU$17:$AU$43,MATCH(7,$AV$17:$AV$43,0)),0) -> 579.25 | BD23: =IF($AU$45=0,0,IFERROR(INDEX($AX$17:$AX$43,MATCH(7,$AV$17:$AV$43,0))+INDEX($AW$17:$AW$43,MATCH(7,$AV$17:$AV$43,0)),1)) -> 0.65043534 | BJ23: =IF(7>$BG$17,"",INDEX($AT$17:$AT$43,MATCH(7,$AV$17:$AV$43,0))) -> Oolong Tea 300ml | BK23: =IF(7>$BG$17,"",INDEX($AU$17:$AU$43,MATCH(7,$AV$17:$AV$43,0))) -> 579.25 | BM23: =IF('Item Purchases'!$B10="","",'Item Purchases'!$B10) -> BBMG 90G | BN23: =IF(AND(BM23<>"",'Item Purchases'!$W10=1,'Item Purchases'!$AN10<>"Discontinued",N('Item Purchases'!$C10)>0),1,0) -> 1 | BO23: =N('Storehouse Replenishment Schedu'!$CR10) -> 472 | BP23: =N('Item Purchases'!$E10) -> 94 | BQ23: =N('Item Purchases'!$C10) -> 36.2 | BR23: =IF(BN23=1,BO23/BQ23,"") -> 13.038674 | BS23: =IF(BN23=1,(BO23+BP23)/BQ23,"") -> 15.635359 | BT23: =IF(BN23=1,BP23/BQ23,"") -> 2.5966851 | BU23: =N('Storehouse Replenishment Schedu'!$CP10) -> 456 | BV23: =IF(BM23="",0,SUMIFS('Daily Data'!$G$2:$G$1000,'Daily Data'!$E$2:$E$1000,BM23)) -> 456 | BW23: =CC23-BV23 -> 0 | BX23: =IF(BN23<>1,"",IF(BO23<=0,IF(BT23<='Item Purchases'!$E$38,"EMPTY - ORDER NOW","EMPTY - PLAN ORDER"),IF(BR23<='Item Purchases'!$E$51,"ORDER NOW",IF(BT23<='Item Purchases'!$E$38,"TRANSFER TO PANTRY",IF(BR23<='Item Purchases'!$E$39,"WATCH","OK"))))) -> TRANSFER TO PANTRY | BY23: =IF(BN23=1,SUMPRODUCT(($BN$17:$BN$43=1)*(($BR$17:$BR$43<BR23)+($BR$17:$BR$43=BR23)*($BT$17:$BT$43<BT23)))+SUMPRODUCT(($BN$17:$BN23=1)*($BR$17:$BR23=BR23)*($BT$17:$BT23=BT23)),"") -> 23 | BZ23: =IF(CA23>0,COUNTIF($CA$17:$CA$43,">"&CA23)+COUNTIF($CA$17:CA23,CA23),"") | CA23: =IF(AND(BM23<>"",'Item Purchases'!$W10=1),ABS(BW23)*1000+CB23,0) -> 0 | CB23: =N('Storehouse Replenishment Schedu'!$CX10) -> 0 | CC23: =BU23-CB23 -> 456 | CD23: =IF('Storehouse Replenishment Schedu'!$CY10="","",'Storehouse Replenishment Schedu'!$CY10) | CG23: =INDEX('Storehouse Replenishment Schedu'!$D$2:$CO$2,1,19) -> 46272 | CH23: =IF(CG23="","",TEXT(CG23,"dd mmm")) -> 07 Sep | CI23: =SUMPRODUCT(INDEX('Storehouse Replenishment Schedu'!$D$4:$CO$30,0,19)*('Item Purchases'!$W$4:$W$30=1)) -> 336 | CJ23: =SUMPRODUCT(INDEX('Storehouse Replenishment Schedu'!$D$4:$CO$30,0,20)*('Item Purchases'!$W$4:$W$30=1)) -> 144 | CK23: =IF(CG23="",0,SUMIFS('Daily Data'!$G$2:$G$1000,'Daily Data'!$A$2:$A$1000,CG23)) -> 336 | CL23: =SUMPRODUCT(INDEX('Storehouse Replenishment Schedu'!$D$4:$CO$30,0,19))-CK23 -> 0 | CM23: =ABS(CL23) -> 0 | CT23: =IF(AND(BM23<>"",'Item Purchases'!$W10=1,ISNUMBER('Item Purchases'!$AQ10),'Item Purchases'!$AS10<>"DISCONTINUED",'Item Purchases'!$AS10<>"NEED MORE DATA"),1,0) -> 1 | CU23: =IF(CT23=1,SUMPRODUCT(($CT$17:$CT$43=1)*('Item Purchases'!$AQ$4:$AQ$30<'Item Purchases'!$AQ10))+SUMPRODUCT(($CT$17:$CT23=1)*('Item Purchases'!$AQ$4:$AQ10='Item Purchases'!$AQ10)),"") -> 25
AB24: Needle centre (0-100) | AC24: =MIN(MAX(SUMPRODUCT((ROW($AD$17:$AD$18)-ROW($AD$17)+1<$AC$23)*$AD$17:$AD$18)+INDEX($AD$17:$AD$18,$AC$23)/2,$AC$13/2),100-$AC$13/2) -> 73.763251 | AH24: =IF(AJ24="","",TEXT(AJ24,"dd mmm")) -> 10 Sep | AI24: =IF(AJ24="","",SUMIFS('Daily Data'!$I$2:$I$1000,'Daily Data'!$A$2:$A$1000,AJ24,'Daily Data'!$M$2:$M$1000,1)) -> 291 | AJ24: ='Daily Data'!$R$10 -> 46275 | AK24: =IF(AJ24="","",COUNTIFS('Daily Data'!$A$2:$A$1000,AJ24,'Daily Data'!$M$2:$M$1000,1,'Daily Data'!$L$2:$L$1000,1)) -> 25 | AP24: =IF('Item Purchases'!$B$11="","",'Item Purchases'!$B$11) -> Lays Potato Chips (Original) 50g | AQ24: =IF(AP24="","",SUMIFS('Daily Data'!$I$2:$I$1000,'Daily Data'!$E$2:$E$1000,AP24,'Daily Data'!$M$2:$M$1000,1)) -> 85 | AR24: =IF(AP24="","",SUMPRODUCT(ISNUMBER($AQ$17:$AQ$43)*($AQ$17:$AQ$43>AQ24))+SUMPRODUCT(ISNUMBER($AQ$17:AQ24)*($AQ$17:AQ24=AQ24))) -> 19 | AT24: =AP24 -> Lays Potato Chips (Original) 50g | AU24: =IF(AT24="","",SUMIFS('Daily Data'!$K$2:$K$1000,'Daily Data'!$E$2:$E$1000,AT24,'Daily Data'!$M$2:$M$1000,1)) -> 293.93 | AV24: =IF(OR(AT24="",N(AU24)<=0),"",SUMPRODUCT(ISNUMBER($AU$17:$AU$43)*($AU$17:$AU$43>AU24))+SUMPRODUCT(ISNUMBER($AU$17:AU24)*($AU$17:AU24=AU24))) -> 13 | AW24: =IF(AV24="","",AU24/$AU$45) -> 0.028564112 | AX24: =IF(AV24="","",SUMIFS($AU$17:$AU$43,$AV$17:$AV$43,"<"&AV24)/$AU$45) -> 0.83895946 | AY24: =IF(AT24="","",IF(AV24="","-",IF(AX24<'Item Purchases'!$E$49,"A",IF(AX24<'Item Purchases'!$E$50,"B","C")))) -> B | BA24: 8 | BB24: =IFERROR(LEFT(INDEX($AT$17:$AT$43,MATCH(8,$AV$17:$AV$43,0)),20),"") -> Milo 200ml | BC24: =IFERROR(INDEX($AU$17:$AU$43,MATCH(8,$AV$17:$AV$43,0)),0) -> 530.88 | BD24: =IF($AU$45=0,0,IFERROR(INDEX($AX$17:$AX$43,MATCH(8,$AV$17:$AV$43,0))+INDEX($AW$17:$AW$43,MATCH(8,$AV$17:$AV$43,0)),1)) -> 0.70202625 | BJ24: =IF(8>$BG$17,"",INDEX($AT$17:$AT$43,MATCH(8,$AV$17:$AV$43,0))) -> Milo 200ml | BK24: =IF(8>$BG$17,"",INDEX($AU$17:$AU$43,MATCH(8,$AV$17:$AV$43,0))) -> 530.88 | BM24: =IF('Item Purchases'!$B11="","",'Item Purchases'!$B11) -> Lays Potato Chips (Original) 50g | BN24: =IF(AND(BM24<>"",'Item Purchases'!$W11=1,'Item Purchases'!$AN11<>"Discontinued",N('Item Purchases'!$C11)>0),1,0) -> 1 | BO24: =N('Storehouse Replenishment Schedu'!$CR11) -> 0 | BP24: =N('Item Purchases'!$E11) -> 20 | BQ24: =N('Item Purchases'!$C11) -> 3.8636364 | BR24: =IF(BN24=1,BO24/BQ24,"") -> 0 | BS24: =IF(BN24=1,(BO24+BP24)/BQ24,"") -> 5.1764706 | BT24: =IF(BN24=1,BP24/BQ24,"") -> 5.1764706 | BU24: =N('Storehouse Replenishment Schedu'!$CP11) -> 72 | BV24: =IF(BM24="",0,SUMIFS('Daily Data'!$G$2:$G$1000,'Daily Data'!$E$2:$E$1000,BM24)) -> 72 | BW24: =CC24-BV24 -> 0 | BX24: =IF(BN24<>1,"",IF(BO24<=0,IF(BT24<='Item Purchases'!$E$38,"EMPTY - ORDER NOW","EMPTY - PLAN ORDER"),IF(BR24<='Item Purchases'!$E$51,"ORDER NOW",IF(BT24<='Item Purchases'!$E$38,"TRANSFER TO PANTRY",IF(BR24<='Item Purchases'!$E$39,"WATCH","OK"))))) -> EMPTY - ORDER NOW | BY24: =IF(BN24=1,SUMPRODUCT(($BN$17:$BN$43=1)*(($BR$17:$BR$43<BR24)+($BR$17:$BR$43=BR24)*($BT$17:$BT$43<BT24)))+SUMPRODUCT(($BN$17:$BN24=1)*($BR$17:$BR24=BR24)*($BT$17:$BT24=BT24)),"") -> 9 | BZ24: =IF(CA24>0,COUNTIF($CA$17:$CA$43,">"&CA24)+COUNTIF($CA$17:CA24,CA24),"") | CA24: =IF(AND(BM24<>"",'Item Purchases'!$W11=1),ABS(BW24)*1000+CB24,0) -> 0 | CB24: =N('Storehouse Replenishment Schedu'!$CX11) -> 0 | CC24: =BU24-CB24 -> 72 | CD24: =IF('Storehouse Replenishment Schedu'!$CY11="","",'Storehouse Replenishment Schedu'!$CY11) | CG24: =INDEX('Storehouse Replenishment Schedu'!$D$2:$CO$2,1,22) -> 46273 | CH24: =IF(CG24="","",TEXT(CG24,"dd mmm")) -> 08 Sep | CI24: =SUMPRODUCT(INDEX('Storehouse Replenishment Schedu'!$D$4:$CO$30,0,22)*('Item Purchases'!$W$4:$W$30=1)) -> 555 | CJ24: =SUMPRODUCT(INDEX('Storehouse Replenishment Schedu'!$D$4:$CO$30,0,23)*('Item Purchases'!$W$4:$W$30=1)) -> 914 | CK24: =IF(CG24="",0,SUMIFS('Daily Data'!$G$2:$G$1000,'Daily Data'!$A$2:$A$1000,CG24)) -> 555 | CL24: =SUMPRODUCT(INDEX('Storehouse Replenishment Schedu'!$D$4:$CO$30,0,22))-CK24 -> 0 | CM24: =ABS(CL24) -> 0 | CT24: =IF(AND(BM24<>"",'Item Purchases'!$W11=1,ISNUMBER('Item Purchases'!$AQ11),'Item Purchases'!$AS11<>"DISCONTINUED",'Item Purchases'!$AS11<>"NEED MORE DATA"),1,0) -> 1 | CU24: =IF(CT24=1,SUMPRODUCT(($CT$17:$CT$43=1)*('Item Purchases'!$AQ$4:$AQ$30<'Item Purchases'!$AQ11))+SUMPRODUCT(($CT$17:$CT24=1)*('Item Purchases'!$AQ$4:$AQ11='Item Purchases'!$AQ11)),"") -> 7
AH25: =IF(AJ25="","",TEXT(AJ25,"dd mmm")) -> 11 Sep | AI25: =IF(AJ25="","",SUMIFS('Daily Data'!$I$2:$I$1000,'Daily Data'!$A$2:$A$1000,AJ25,'Daily Data'!$M$2:$M$1000,1)) -> 294 | AJ25: ='Daily Data'!$R$11 -> 46276 | AK25: =IF(AJ25="","",COUNTIFS('Daily Data'!$A$2:$A$1000,AJ25,'Daily Data'!$M$2:$M$1000,1,'Daily Data'!$L$2:$L$1000,1)) -> 25 | AP25: =IF('Item Purchases'!$B$12="","",'Item Purchases'!$B$12) -> Lays Double Crunch - Seaweed Flav (50g) | AQ25: =IF(AP25="","",SUMIFS('Daily Data'!$I$2:$I$1000,'Daily Data'!$E$2:$E$1000,AP25,'Daily Data'!$M$2:$M$1000,1)) -> 315 | AR25: =IF(AP25="","",SUMPRODUCT(ISNUMBER($AQ$17:$AQ$43)*($AQ$17:$AQ$43>AQ25))+SUMPRODUCT(ISNUMBER($AQ$17:AQ25)*($AQ$17:AQ25=AQ25))) -> 7 | AT25: =AP25 -> Lays Double Crunch - Seaweed Flav (50g) | AU25: =IF(AT25="","",SUMIFS('Daily Data'!$K$2:$K$1000,'Daily Data'!$E$2:$E$1000,AT25,'Daily Data'!$M$2:$M$1000,1)) -> 1260 | AV25: =IF(OR(AT25="",N(AU25)<=0),"",SUMPRODUCT(ISNUMBER($AU$17:$AU$43)*($AU$17:$AU$43>AU25))+SUMPRODUCT(ISNUMBER($AU$17:AU25)*($AU$17:AU25=AU25))) -> 1 | AW25: =IF(AV25="","",AU25/$AU$45) -> 0.12244678 | AX25: =IF(AV25="","",SUMIFS($AU$17:$AU$43,$AV$17:$AV$43,"<"&AV25)/$AU$45) -> 0 | AY25: =IF(AT25="","",IF(AV25="","-",IF(AX25<'Item Purchases'!$E$49,"A",IF(AX25<'Item Purchases'!$E$50,"B","C")))) -> A | BA25: 9 | BB25: =IFERROR(LEFT(INDEX($AT$17:$AT$43,MATCH(9,$AV$17:$AV$43,0)),20),"") -> BingRae Banana Milk | BC25: =IFERROR(INDEX($AU$17:$AU$43,MATCH(9,$AV$17:$AV$43,0)),0) -> 407.868 | BD25: =IF($AU$45=0,0,IFERROR(INDEX($AX$17:$AX$43,MATCH(9,$AV$17:$AV$43,0))+INDEX($AW$17:$AW$43,MATCH(9,$AV$17:$AV$43,0)),1)) -> 0.74166286 | BJ25: =IF(9>$BG$17,"",INDEX($AT$17:$AT$43,MATCH(9,$AV$17:$AV$43,0))) -> BingRae Banana Milk 200ml | BK25: =IF(9>$BG$17,"",INDEX($AU$17:$AU$43,MATCH(9,$AV$17:$AV$43,0))) -> 407.868 | BM25: =IF('Item Purchases'!$B12="","",'Item Purchases'!$B12) -> Lays Double Crunch - Seaweed Flav (50g) | BN25: =IF(AND(BM25<>"",'Item Purchases'!$W12=1,'Item Purchases'!$AN12<>"Discontinued",N('Item Purchases'!$C12)>0),1,0) -> 1 | BO25: =N('Storehouse Replenishment Schedu'!$CR12) -> 93 | BP25: =N('Item Purchases'!$E12) -> 39 | BQ25: =N('Item Purchases'!$C12) -> 15.75 | BR25: =IF(BN25=1,BO25/BQ25,"") -> 5.9047619 | BS25: =IF(BN25=1,(BO25+BP25)/BQ25,"") -> 8.3809524 | BT25: =IF(BN25=1,BP25/BQ25,"") -> 2.4761905 | BU25: =N('Storehouse Replenishment Schedu'!$CP12) -> 332 | BV25: =IF(BM25="",0,SUMIFS('Daily Data'!$G$2:$G$1000,'Daily Data'!$E$2:$E$1000,BM25)) -> 330 | BW25: =CC25-BV25 -> 0 | BX25: =IF(BN25<>1,"",IF(BO25<=0,IF(BT25<='Item Purchases'!$E$38,"EMPTY - ORDER NOW","EMPTY - PLAN ORDER"),IF(BR25<='Item Purchases'!$E$51,"ORDER NOW",IF(BT25<='Item Purchases'!$E$38,"TRANSFER TO PANTRY",IF(BR25<='Item Purchases'!$E$39,"WATCH","OK"))))) -> TRANSFER TO PANTRY | BY25: =IF(BN25=1,SUMPRODUCT(($BN$17:$BN$43=1)*(($BR$17:$BR$43<BR25)+($BR$17:$BR$43=BR25)*($BT$17:$BT$43<BT25)))+SUMPRODUCT(($BN$17:$BN25=1)*($BR$17:$BR25=BR25)*($BT$17:$BT25=BT25)),"") -> 17 | BZ25: =IF(CA25>0,COUNTIF($CA$17:$CA$43,">"&CA25)+COUNTIF($CA$17:CA25,CA25),"") -> 1 | CA25: =IF(AND(BM25<>"",'Item Purchases'!$W12=1),ABS(BW25)*1000+CB25,0) -> 2 | CB25: =N('Storehouse Replenishment Schedu'!$CX12) -> 2 | CC25: =BU25-CB25 -> 330 | CD25: =IF('Storehouse Replenishment Schedu'!$CY12="","",'Storehouse Replenishment Schedu'!$CY12) | CG25: =INDEX('Storehouse Replenishment Schedu'!$D$2:$CO$2,1,25) -> 46274 | CH25: =IF(CG25="","",TEXT(CG25,"dd mmm")) -> 09 Sep | CI25: =SUMPRODUCT(INDEX('Storehouse Replenishment Schedu'!$D$4:$CO$30,0,25)*('Item Purchases'!$W$4:$W$30=1)) -> 274 | CJ25: =SUMPRODUCT(INDEX('Storehouse Replenishment Schedu'!$D$4:$CO$30,0,26)*('Item Purchases'!$W$4:$W$30=1)) -> 168 | CK25: =IF(CG25="",0,SUMIFS('Daily Data'!$G$2:$G$1000,'Daily Data'!$A$2:$A$1000,CG25)) -> 274 | CL25: =SUMPRODUCT(INDEX('Storehouse Replenishment Schedu'!$D$4:$CO$30,0,25))-CK25 -> 0 | CM25: =ABS(CL25) -> 0 | CT25: =IF(AND(BM25<>"",'Item Purchases'!$W12=1,ISNUMBER('Item Purchases'!$AQ12),'Item Purchases'!$AS12<>"DISCONTINUED",'Item Purchases'!$AS12<>"NEED MORE DATA"),1,0) -> 1 | CU25: =IF(CT25=1,SUMPRODUCT(($CT$17:$CT$43=1)*('Item Purchases'!$AQ$4:$AQ$30<'Item Purchases'!$AQ12))+SUMPRODUCT(($CT$17:$CT25=1)*('Item Purchases'!$AQ$4:$AQ12='Item Purchases'!$AQ12)),"") -> 18
AB26: BEVERAGES (Coffee / Tea / Other) | AH26: =IF(AJ26="","",TEXT(AJ26,"dd mmm")) -> 14 Sep | AI26: =IF(AJ26="","",SUMIFS('Daily Data'!$I$2:$I$1000,'Daily Data'!$A$2:$A$1000,AJ26,'Daily Data'!$M$2:$M$1000,1)) -> 190 | AJ26: ='Daily Data'!$R$12 -> 46279 | AK26: =IF(AJ26="","",COUNTIFS('Daily Data'!$A$2:$A$1000,AJ26,'Daily Data'!$M$2:$M$1000,1,'Daily Data'!$L$2:$L$1000,1)) -> 25 | AM26: Week | AN26: Units | AP26: =IF('Item Purchases'!$B$13="","",'Item Purchases'!$B$13) -> Munchy Oat Krunch - Dark Choco | AQ26: =IF(AP26="","",SUMIFS('Daily Data'!$I$2:$I$1000,'Daily Data'!$E$2:$E$1000,AP26,'Daily Data'!$M$2:$M$1000,1)) -> 285 | AR26: =IF(AP26="","",SUMPRODUCT(ISNUMBER($AQ$17:$AQ$43)*($AQ$17:$AQ$43>AQ26))+SUMPRODUCT(ISNUMBER($AQ$17:AQ26)*($AQ$17:AQ26=AQ26))) -> 9 | AT26: =AP26 -> Munchy Oat Krunch - Dark Choco | AU26: =IF(AT26="","",SUMIFS('Daily Data'!$K$2:$K$1000,'Daily Data'!$E$2:$E$1000,AT26,'Daily Data'!$M$2:$M$1000,1)) -> 208.05 | AV26: =IF(OR(AT26="",N(AU26)<=0),"",SUMPRODUCT(ISNUMBER($AU$17:$AU$43)*($AU$17:$AU$43>AU26))+SUMPRODUCT(ISNUMBER($AU$17:AU26)*($AU$17:AU26=AU26))) -> 15 | AW26: =IF(AV26="","",AU26/$AU$45) -> 0.020218295 | AX26: =IF(AV26="","",SUMIFS($AU$17:$AU$43,$AV$17:$AV$43,"<"&AV26)/$AU$45) -> 0.88825701 | AY26: =IF(AT26="","",IF(AV26="","-",IF(AX26<'Item Purchases'!$E$49,"A",IF(AX26<'Item Purchases'!$E$50,"B","C")))) -> B | BA26: 10 | BB26: =IFERROR(LEFT(INDEX($AT$17:$AT$43,MATCH(10,$AV$17:$AV$43,0)),20),"") -> Vsoy Soya Bean 250m | BC26: =IFERROR(INDEX($AU$17:$AU$43,MATCH(10,$AV$17:$AV$43,0)),0) -> 338.75 | BD26: =IF($AU$45=0,0,IFERROR(INDEX($AX$17:$AX$43,MATCH(10,$AV$17:$AV$43,0))+INDEX($AW$17:$AW$43,MATCH(10,$AV$17:$AV$43,0)),1)) -> 0.77458258 | BM26: =IF('Item Purchases'!$B13="","",'Item Purchases'!$B13) -> Munchy Oat Krunch - Dark Choco | BN26: =IF(AND(BM26<>"",'Item Purchases'!$W13=1,'Item Purchases'!$AN13<>"Discontinued",N('Item Purchases'!$C13)>0),1,0) -> 1 | BO26: =N('Storehouse Replenishment Schedu'!$CR13) -> 0 | BP26: =N('Item Purchases'!$E13) -> 45 | BQ26: =N('Item Purchases'!$C13) -> 15.833333 | BR26: =IF(BN26=1,BO26/BQ26,"") -> 0 | BS26: =IF(BN26=1,(BO26+BP26)/BQ26,"") -> 2.8421053 | BT26: =IF(BN26=1,BP26/BQ26,"") -> 2.8421053 | BU26: =N('Storehouse Replenishment Schedu'!$CP13) -> 285 | BV26: =IF(BM26="",0,SUMIFS('Daily Data'!$G$2:$G$1000,'Daily Data'!$E$2:$E$1000,BM26)) -> 285 | BW26: =CC26-BV26 -> 0 | BX26: =IF(BN26<>1,"",IF(BO26<=0,IF(BT26<='Item Purchases'!$E$38,"EMPTY - ORDER NOW","EMPTY - PLAN ORDER"),IF(BR26<='Item Purchases'!$E$51,"ORDER NOW",IF(BT26<='Item Purchases'!$E$38,"TRANSFER TO PANTRY",IF(BR26<='Item Purchases'!$E$39,"WATCH","OK"))))) -> EMPTY - ORDER NOW | BY26: =IF(BN26=1,SUMPRODUCT(($BN$17:$BN$43=1)*(($BR$17:$BR$43<BR26)+($BR$17:$BR$43=BR26)*($BT$17:$BT$43<BT26)))+SUMPRODUCT(($BN$17:$BN26=1)*($BR$17:$BR26=BR26)*($BT$17:$BT26=BT26)),"") -> 5 | BZ26: =IF(CA26>0,COUNTIF($CA$17:$CA$43,">"&CA26)+COUNTIF($CA$17:CA26,CA26),"") | CA26: =IF(AND(BM26<>"",'Item Purchases'!$W13=1),ABS(BW26)*1000+CB26,0) -> 0 | CB26: =N('Storehouse Replenishment Schedu'!$CX13) -> 0 | CC26: =BU26-CB26 -> 285 | CD26: =IF('Storehouse Replenishment Schedu'!$CY13="","",'Storehouse Replenishment Schedu'!$CY13) | CG26: =INDEX('Storehouse Replenishment Schedu'!$D$2:$CO$2,1,28) -> 46275 | CH26: =IF(CG26="","",TEXT(CG26,"dd mmm")) -> 10 Sep | CI26: =SUMPRODUCT(INDEX('Storehouse Replenishment Schedu'!$D$4:$CO$30,0,28)*('Item Purchases'!$W$4:$W$30=1)) -> 150 | CJ26: =SUMPRODUCT(INDEX('Storehouse Replenishment Schedu'!$D$4:$CO$30,0,29)*('Item Purchases'!$W$4:$W$30=1)) -> 0 | CK26: =IF(CG26="",0,SUMIFS('Daily Data'!$G$2:$G$1000,'Daily Data'!$A$2:$A$1000,CG26)) -> 150 | CL26: =SUMPRODUCT(INDEX('Storehouse Replenishment Schedu'!$D$4:$CO$30,0,28))-CK26 -> 0 | CM26: =ABS(CL26) -> 0 | CT26: =IF(AND(BM26<>"",'Item Purchases'!$W13=1,ISNUMBER('Item Purchases'!$AQ13),'Item Purchases'!$AS13<>"DISCONTINUED",'Item Purchases'!$AS13<>"NEED MORE DATA"),1,0) -> 1 | CU26: =IF(CT26=1,SUMPRODUCT(($CT$17:$CT$43=1)*('Item Purchases'!$AQ$4:$AQ$30<'Item Purchases'!$AQ13))+SUMPRODUCT(($CT$17:$CT26=1)*('Item Purchases'!$AQ$4:$AQ13='Item Purchases'!$AQ13)),"") -> 20
B27: =AB17 -> Sweet | F27: =AB18 -> Savoury | J27: =AB28 -> Coffee | L27: =AB29 -> Tea | O27: =AB30 -> Other | AB27: Type | AC27: Units | AD27: Share % | AE27: Chart label | AF27: Needle | AH27: =IF(AJ27="","",TEXT(AJ27,"dd mmm")) -> 15 Sep | AI27: =IF(AJ27="","",SUMIFS('Daily Data'!$I$2:$I$1000,'Daily Data'!$A$2:$A$1000,AJ27,'Daily Data'!$M$2:$M$1000,1)) -> 189 | AJ27: ='Daily Data'!$R$13 -> 46280 | AK27: =IF(AJ27="","",COUNTIFS('Daily Data'!$A$2:$A$1000,AJ27,'Daily Data'!$M$2:$M$1000,1,'Daily Data'!$L$2:$L$1000,1)) -> 25 | AM27: ='Daily Data'!$P$3 -> Sep Week 1 | AN27: =SUMIFS('Daily Data'!$I$2:$I$1000,'Daily Data'!$C$2:$C$1000,AM27,'Daily Data'!$M$2:$M$1000,1) -> 1141 | AP27: =IF('Item Purchases'!$B$14="","",'Item Purchases'!$B$14) -> Munchy Oat Krunch - Strawberry & Blackcurrant | AQ27: =IF(AP27="","",SUMIFS('Daily Data'!$I$2:$I$1000,'Daily Data'!$E$2:$E$1000,AP27,'Daily Data'!$M$2:$M$1000,1)) -> 182 | AR27: =IF(AP27="","",SUMPRODUCT(ISNUMBER($AQ$17:$AQ$43)*($AQ$17:$AQ$43>AQ27))+SUMPRODUCT(ISNUMBER($AQ$17:AQ27)*($AQ$17:AQ27=AQ27))) -> 15 | AT27: =AP27 -> Munchy Oat Krunch - Strawberry & Blackcurrant | AU27: =IF(AT27="","",SUMIFS('Daily Data'!$K$2:$K$1000,'Daily Data'!$E$2:$E$1000,AT27,'Daily Data'!$M$2:$M$1000,1)) -> 132.86 | AV27: =IF(OR(AT27="",N(AU27)<=0),"",SUMPRODUCT(ISNUMBER($AU$17:$AU$43)*($AU$17:$AU$43>AU27))+SUMPRODUCT(ISNUMBER($AU$17:AU27)*($AU$17:AU27=AU27))) -> 19 | AW27: =IF(AV27="","",AU27/$AU$45) -> 0.012911332 | AX27: =IF(AV27="","",SUMIFS($AU$17:$AU$43,$AV$17:$AV$43,"<"&AV27)/$AU$45) -> 0.95167303 | AY27: =IF(AT27="","",IF(AV27="","-",IF(AX27<'Item Purchases'!$E$49,"A",IF(AX27<'Item Purchases'!$E$50,"B","C")))) -> C | BA27: 11 | BB27: =IFERROR(LEFT(INDEX($AT$17:$AT$43,MATCH(11,$AV$17:$AV$43,0)),20),"") -> COKE ZERO 325ML | BC27: =IFERROR(INDEX($AU$17:$AU$43,MATCH(11,$AV$17:$AV$43,0)),0) -> 338.55 | BD27: =IF($AU$45=0,0,IFERROR(INDEX($AX$17:$AX$43,MATCH(11,$AV$17:$AV$43,0))+INDEX($AW$17:$AW$43,MATCH(11,$AV$17:$AV$43,0)),1)) -> 0.80748286 | BM27: =IF('Item Purchases'!$B14="","",'Item Purchases'!$B14) -> Munchy Oat Krunch - Strawberry & Blackcurrant | BN27: =IF(AND(BM27<>"",'Item Purchases'!$W14=1,'Item Purchases'!$AN14<>"Discontinued",N('Item Purchases'!$C14)>0),1,0) -> 1 | BO27: =N('Storehouse Replenishment Schedu'!$CR14) -> 0 | BP27: =N('Item Purchases'!$E14) -> 37 | BQ27: =N('Item Purchases'!$C14) -> 8.2727273 | BR27: =IF(BN27=1,BO27/BQ27,"") -> 0 | BS27: =IF(BN27=1,(BO27+BP27)/BQ27,"") -> 4.4725275 | BT27: =IF(BN27=1,BP27/BQ27,"") -> 4.4725275 | BU27: =N('Storehouse Replenishment Schedu'!$CP14) -> 210 | BV27: =IF(BM27="",0,SUMIFS('Daily Data'!$G$2:$G$1000,'Daily Data'!$E$2:$E$1000,BM27)) -> 210 | BW27: =CC27-BV27 -> 0 | BX27: =IF(BN27<>1,"",IF(BO27<=0,IF(BT27<='Item Purchases'!$E$38,"EMPTY - ORDER NOW","EMPTY - PLAN ORDER"),IF(BR27<='Item Purchases'!$E$51,"ORDER NOW",IF(BT27<='Item Purchases'!$E$38,"TRANSFER TO PANTRY",IF(BR27<='Item Purchases'!$E$39,"WATCH","OK"))))) -> EMPTY - ORDER NOW | BY27: =IF(BN27=1,SUMPRODUCT(($BN$17:$BN$43=1)*(($BR$17:$BR$43<BR27)+($BR$17:$BR$43=BR27)*($BT$17:$BT$43<BT27)))+SUMPRODUCT(($BN$17:$BN27=1)*($BR$17:$BR27=BR27)*($BT$17:$BT27=BT27)),"") -> 7 | BZ27: =IF(CA27>0,COUNTIF($CA$17:$CA$43,">"&CA27)+COUNTIF($CA$17:CA27,CA27),"") | CA27: =IF(AND(BM27<>"",'Item Purchases'!$W14=1),ABS(BW27)*1000+CB27,0) -> 0 | CB27: =N('Storehouse Replenishment Schedu'!$CX14) -> 0 | CC27: =BU27-CB27 -> 210 | CD27: =IF('Storehouse Replenishment Schedu'!$CY14="","",'Storehouse Replenishment Schedu'!$CY14) | CG27: =INDEX('Storehouse Replenishment Schedu'!$D$2:$CO$2,1,31) -> 46276 | CH27: =IF(CG27="","",TEXT(CG27,"dd mmm")) -> 11 Sep | CI27: =SUMPRODUCT(INDEX('Storehouse Replenishment Schedu'!$D$4:$CO$30,0,31)*('Item Purchases'!$W$4:$W$30=1)) -> 264 | CJ27: =SUMPRODUCT(INDEX('Storehouse Replenishment Schedu'!$D$4:$CO$30,0,32)*('Item Purchases'!$W$4:$W$30=1)) -> 144 | CK27: =IF(CG27="",0,SUMIFS('Daily Data'!$G$2:$G$1000,'Daily Data'!$A$2:$A$1000,CG27)) -> 264 | CL27: =SUMPRODUCT(INDEX('Storehouse Replenishment Schedu'!$D$4:$CO$30,0,31))-CK27 -> 0 | CM27: =ABS(CL27) -> 0 | CT27: =IF(AND(BM27<>"",'Item Purchases'!$W14=1,ISNUMBER('Item Purchases'!$AQ14),'Item Purchases'!$AS14<>"DISCONTINUED",'Item Purchases'!$AS14<>"NEED MORE DATA"),1,0) -> 1 | CU27: =IF(CT27=1,SUMPRODUCT(($CT$17:$CT$43=1)*('Item Purchases'!$AQ$4:$AQ$30<'Item Purchases'!$AQ14))+SUMPRODUCT(($CT$17:$CT27=1)*('Item Purchases'!$AQ$4:$AQ14='Item Purchases'!$AQ14)),"") -> 12
